Workbook
Name Slicer_BusinessUnit: #N/A
Name Slicer_DepartmentType: #N/A
Name Slicer_Training_Program_Name: #N/A

Sheet HR ANALYTICS DATASET FOR 30 DAT
A1: Employee ID | B1: StartDate | C1: Title | D1: BusinessUnit | E1: EmployeeStatus | F1: EmployeeType | G1: PayZone | H1: EmployeeClassificationType | I1: DepartmentType | J1: Division | K1: DOB | L1: State | M1: GenderCode | N1: RaceDesc | O1: MaritalDesc | P1: Performance Score | Q1: Current Employee Rating | R1: Survey Date | S1: Engagement Score | T1: Satisfaction Score | U1: Work-Life Balance Score | V1: Training Date | W1: Training Program Name | X1: Training Type | Y1: Training Outcome | Z1: Training Duration(Days) | AA1: Training Cost | AB1: Age | AC1: Age Group | AD1: Tenure | AE1: Engagement Level | AF1: Satisfaction Level | AG1: Performance Category | AH1: Training Efficiency
A2: 3427 | B2: 43728 | C2: Production Technician I | D2: CCDR | E2: Active | F2: Contract | G2: Zone C | H2: Temporary | I2: Production | J2: Finance & Accounting | K2: 25483 | L2: MA | M2: Female | N2: White | O2: Widowed | P2: Fully Meets | Q2: 4 | R2: 44940 | S2: 1 | T2: 2 | U2: 3 | V2: 45122 | W2: Leadership Development | X2: Internal | Y2: Failed | Z2: 2 | AA2: 606.11 | AB2: 50 | AC2: {=_xlfn.IFS(AB2 <=29, "Young Adult", AB2 <=44, "Adult", AB2 <=59, "Middle Age", AB2 > 59, "Old")} -> Middle Age | AD2: =DATEDIF(B2, TODAY(), "Y") -> 6 | AE2: {=_xlfn.IFS(S2 < 3, "Low", S2 <= 4, "Medium", S2 > 4, "High")} -> Low | AF2: {=_xlfn.IFS(T2 < 3, "Unsatisfied", T2 <= 4, "Neutral", T2 > 4, "Satisfied" )} -> Unsatisfied | AG2: {=_xlfn.IFS(Q2 < 3, "Needs Improvement", Q2 <= 4, "Good", Q2 > 4, "Excellent" )} -> Good | AH2: =IF(AND(Y2 = "Passed", Q2 > 4), "Highly Effective", IF(AND(Y2 = "Completed", Q2 >= 3), "Effective", "Needs Improvement")) -> Needs Improvement
A3: 3428 | B3: 44968 | C3: Production Technician I | D3: EW | E3: Active | F3: Contract | G3: Zone A | H3: Part-Time | I3: Production | J3: Aerial | K3: 23984 | L3: MA | M3: Male | N3: Hispanic | O3: Widowed | P3: Fully Meets | Q3: 3 | R3: 44813 | S3: 2 | T3: 1 | U3: 5 | V3: 44816 | W3: Customer Service | X3: External | Y3: Incomplete | Z3: 4 | AA3: 673.02 | AB3: 58 | AC3: {=_xlfn.IFS(AB3 <=29, "Young Adult", AB3 <=44, "Adult", AB3 <=59, "Middle Age", AB3 > 59, "Old")} -> Middle Age | AD3: =DATEDIF(B3, TODAY(), "Y") -> 3 | AE3: {=_xlfn.IFS(S3 < 3, "Low", S3 <= 4, "Medium", S3 > 4, "High")} -> Low | AF3: {=_xlfn.IFS(T3 < 3, "Unsatisfied", T3 <= 4, "Neutral", T3 > 4, "Satisfied" )} -> Unsatisfied | AG3: {=_xlfn.IFS(Q3 < 3, "Needs Improvement", Q3 <= 4, "Good", Q3 > 4, "Excellent" )} -> Good | AH3: =IF(AND(Y3 = "Passed", Q3 > 4), "Highly Effective", IF(AND(Y3 = "Completed", Q3 >= 3), "Effective", "Needs Improvement")) -> Needs Improvement
A4: 3429 | B4: 43444 | C4: Area Sales Manager | D4: PL | E4: Active | F4: Full-Time | G4: Zone B | H4: Part-Time | I4: Sales | J4: General - Sga | K4: 33517 | L4: MA | M4: Male | N4: Hispanic | O4: Widowed | P4: Fully Meets | Q4: 4 | R4: 45073 | S4: 1 | T4: 2 | U4: 1 | V4: 44786 | W4: Leadership Development | X4: External | Y4: Failed | Z4: 2 | AA4: 413.28 | AB4: 27 | AC4: {=_xlfn.IFS(AB4 <=29, "Young Adult", AB4 <=44, "Adult", AB4 <=59, "Middle Age", AB4 > 59, "Old")} -> Young Adult | AD4: =DATEDIF(B4, TODAY(), "Y") -> 7 | AE4: {=_xlfn.IFS(S4 < 3, "Low", S4 <= 4, "Medium", S4 > 4, "High")} -> Low | AF4: {=_xlfn.IFS(T4 < 3, "Unsatisfied", T4 <= 4, "Neutral", T4 > 4, "Satisfied" )} -> Unsatisfied | AG4: {=_xlfn.IFS(Q4 < 3, "Needs Improvement", Q4 <= 4, "Good", Q4 > 4, "Excellent" )} -> Good | AH4: =IF(AND(Y4 = "Passed", Q4 > 4), "Highly Effective", IF(AND(Y4 = "Completed", Q4 >= 3), "Effective", "Needs Improvement")) -> Needs Improvement
A5: 3430 | B5: 44368 | C5: Area Sales Manager | D5: CCDR | E5: Active | F5: Contract | G5: Zone A | H5: Full-Time | I5: Sales | J5: Finance & Accounting | K5: 35889 | L5: ND | M5: Male | N5: Other | O5: Single | P5: Fully Meets | Q5: 2 | R5: 45093 | S5: 5 | T5: 5 | U5: 4 | V5: 44910 | W5: Project Management | X5: External | Y5: Completed | Z5: 3 | AA5: 663.78 | AB5: 23 | AC5: {=_xlfn.IFS(AB5 <=29, "Young Adult", AB5 <=44, "Adult", AB5 <=59, "Middle Age", AB5 > 59, "Old")} -> Young Adult | AD5: =DATEDIF(B5, TODAY(), "Y") -> 4 | AE5: {=_xlfn.IFS(S5 < 3, "Low", S5 <= 4, "Medium", S5 > 4, "High")} -> High | AF5: {=_xlfn.IFS(T5 < 3, "Unsatisfied", T5 <= 4, "Neutral", T5 > 4, "Satisfied" )} -> Satisfied | AG5: {=_xlfn.IFS(Q5 < 3, "Needs Improvement", Q5 <= 4, "Good", Q5 > 4, "Excellent" )} -> Needs Improvement | AH5: =IF(AND(Y5 = "Passed", Q5 > 4), "Highly Effective", IF(AND(Y5 = "Completed", Q5 >= 3), "Effective", "Needs Improvement")) -> Needs Improvement
A6: 3431 | B6: 43645 | C6: Area Sales Manager | D6: TNS | E6: Active | F6: Contract | G6: Zone A | H6: Temporary | I6: Sales | J6: General - Con | K6: 25444 | L6: FL | M6: Female | N6: Other | O6: Married | P6: Fully Meets | Q6: 3 | R6: 44890 | S6: 2 | T6: 5 | U6: 3 | V6: 45120 | W6: Technical Skills | X6: External | Y6: Failed | Z6: 5 | AA6: 399.03 | AB6: 50 | AC6: {=_xlfn.IFS(AB6 <=29, "Young Adult", AB6 <=44, "Adult", AB6 <=59, "Middle Age", AB6 > 59, "Old")} -> Middle Age | AD6: =DATEDIF(B6, TODAY(), "Y") -> 6 | AE6: {=_xlfn.IFS(S6 < 3, "Low", S6 <= 4, "Medium", S6 > 4, "High")} -> Low | AF6: {=_xlfn.IFS(T6 < 3, "Unsatisfied", T6 <= 4, "Neutral", T6 > 4, "Satisfied" )} -> Satisfied | AG6: {=_xlfn.IFS(Q6 < 3, "Needs Improvement", Q6 <= 4, "Good", Q6 > 4, "Excellent" )} -> Good | AH6: =IF(AND(Y6 = "Passed", Q6 > 4), "Highly Effective", IF(AND(Y6 = "Completed", Q6 >= 3), "Effective", "Needs Improvement")) -> Needs Improvement
A7: 3432 | B7: 43847 | C7: Area Sales Manager | D7: BPC | E7: Active | F7: Contract | G7: Zone B | H7: Full-Time | I7: Sales | J7: Field Operations | K7: 17991 | L7: CT | M7: Male | N7: Black | O7: Married | P7: Fully Meets | Q7: 3 | R7: 44907 | S7: 2 | T7: 3 | U7: 5 | V7: 45034 | W7: Project Management | X7: Internal | Y7: Passed | Z7: 2 | AA7: 820.33 | AB7: 71 | AC7: {=_xlfn.IFS(AB7 <=29, "Young Adult", AB7 <=44, "Adult", AB7 <=59, "Middle Age", AB7 > 59, "Old")} -> Old | AD7: =DATEDIF(B7, TODAY(), "Y") -> 6 | AE7: {=_xlfn.IFS(S7 < 3, "Low", S7 <= 4, "Medium", S7 > 4, "High")} -> Low | AF7: {=_xlfn.IFS(T7 < 3, "Unsatisfied", T7 <= 4, "Neutral", T7 > 4, "Satisfied" )} -> Neutral | AG7: {=_xlfn.IFS(Q7 < 3, "Needs Improvement", Q7 <= 4, "Good", Q7 > 4, "Excellent" )} -> Good | AH7: =IF(AND(Y7 = "Passed", Q7 > 4), "Highly Effective", IF(AND(Y7 = "Completed", Q7 >= 3), "Effective", "Needs Improvement")) -> Needs Improvement
A8: 3433 | B8: 44657 | C8: Area Sales Manager | D8: WBL | E8: Active | F8: Full-Time | G8: Zone B | H8: Temporary | I8: Sales | J8: General - Eng | K8: 15523 | L8: CA | M8: Female | N8: Hispanic | O8: Divorced | P8: Exceeds | Q8: 4 | R8: 45010 | S8: 1 | T8: 5 | U8: 2 | V8: 44779 | W8: Customer Service | X8: External | Y8: Passed | Z8: 5 | AA8: 295.08 | AB8: 80 | AC8: {=_xlfn.IFS(AB8 <=29, "Young Adult", AB8 <=44, "Adult", AB8 <=59, "Middle Age", AB8 > 59, "Old")} -> Old | AD8: =DATEDIF(B8, TODAY(), "Y") -> 4 | AE8: {=_xlfn.IFS(S8 < 3, "Low", S8 <= 4, "Medium", S8 > 4, "High")} -> Low | AF8: {=_xlfn.IFS(T8 < 3, "Unsatisfied", T8 <= 4, "Neutral", T8 > 4, "Satisfied" )} -> Satisfied | AG8: {=_xlfn.IFS(Q8 < 3, "Needs Improvement", Q8 <= 4, "Good", Q8 > 4, "Excellent" )} -> Good | AH8: =IF(AND(Y8 = "Passed", Q8 > 4), "Highly Effective", IF(AND(Y8 = "Completed", Q8 >= 3), "Effective", "Needs Improvement")) -> Needs Improvement
A9: 3434 | B9: 44141 | C9: Area Sales Manager | D9: CCDR | E9: Active | F9: Contract | G9: Zone C | H9: Full-Time | I9: Sales | J9: Engineers | K9: 20886 | L9: OR | M9: Female | N9: White | O9: Divorced | P9: Fully Meets | Q9: 2 | R9: 45037 | S9: 1 | T9: 4 | U9: 2 | V9: 44841 | W9: Leadership Development | X9: Internal | Y9: Passed | Z9: 3 | AA9: 790.15 | AB9: 63 | AC9: {=_xlfn.IFS(AB9 <=29, "Young Adult", AB9 <=44, "Adult", AB9 <=59, "Middle Age", AB9 > 59, "Old")} -> Old | AD9: =DATEDIF(B9, TODAY(), "Y") -> 5 | AE9: {=_xlfn.IFS(S9 < 3, "Low", S9 <= 4, "Medium", S9 > 4, "High")} -> Low | AF9: {=_xlfn.IFS(T9 < 3, "Unsatisfied", T9 <= 4, "Neutral", T9 > 4, "Satisfied" )} -> Neutral | AG9: {=_xlfn.IFS(Q9 < 3, "Needs Improvement", Q9 <= 4, "Good", Q9 > 4, "Excellent" )} -> Needs Improvement | AH9: =IF(AND(Y9 = "Passed", Q9 > 4), "Highly Effective", IF(AND(Y9 = "Completed", Q9 >= 3), "Effective", "Needs Improvement")) -> Needs Improvement
A10: 3435 | B10: 43330 | C10: Area Sales Manager | D10: NEL | E10: Active | F10: Contract | G10: Zone B | H10: Part-Time | I10: Sales | J10: Executive | K10: 27164 | L10: TX | M10: Male | N10: Black | O10: Widowed | P10: Exceeds | Q10: 3 | R10: 44904 | S10: 4 | T10: 3 | U10: 3 | V10: 45126 | W10: Customer Service | X10: Internal | Y10: Passed | Z10: 3 | AA10: 798.4 | AB10: 44 | AC10: {=_xlfn.IFS(AB10 <=29, "Young Adult", AB10 <=44, "Adult", AB10 <=59, "Middle Age", AB10 > 59, "Old")} -> Adult | AD10: =DATEDIF(B10, TODAY(), "Y") -> 7 | AE10: {=_xlfn.IFS(S10 < 3, "Low", S10 <= 4, "Medium", S10 > 4, "High")} -> Medium | AF10: {=_xlfn.IFS(T10 < 3, "Unsatisfied", T10 <= 4, "Neutral", T10 > 4, "Satisfied" )} -> Neutral | AG10: {=_xlfn.IFS(Q10 < 3, "Needs Improvement", Q10 <= 4, "Good", Q10 > 4, "Excellent" )} -> Good | AH10: =IF(AND(Y10 = "Passed", Q10 > 4), "Highly Effective", IF(AND(Y10 = "Completed", Q10 >= 3), "Effective", "Needs Improvement")) -> Needs Improvement
A11: 3436 | B11: 44582 | C11: Area Sales Manager | D11: BPC | E11: Active | F11: Part-Time | G11: Zone B | H11: Temporary | I11: Sales | J11: Engineers | K11: 18213 | L11: TX | M11: Male | N11: Asian | O11: Widowed | P11: Fully Meets | Q11: 5 | R11: 45137 | S11: 5 | T11: 5 | U11: 2 | V11: 45025 | W11: Leadership Development | X11: Internal | Y11: Failed | Z11: 5 | AA11: 192.61 | AB11: 73 | AC11: {=_xlfn.IFS(AB11 <=29, "Young Adult", AB11 <=44, "Adult", AB11 <=59, "Middle Age", AB11 > 59, "Old")} -> Old | AD11: =DATEDIF(B11, TODAY(), "Y") -> 4 | AE11: {=_xlfn.IFS(S11 < 3, "Low", S11 <= 4, "Medium", S11 > 4, "High")} -> High | AF11: {=_xlfn.IFS(T11 < 3, "Unsatisfied", T11 <= 4, "Neutral", T11 > 4, "Satisfied" )} -> Satisfied | AG11: {=_xlfn.IFS(Q11 < 3, "Needs Improvement", Q11 <= 4, "Good", Q11 > 4, "Excellent" )} -> Excellent | AH11: =IF(AND(Y11 = "Passed", Q11 > 4), "Highly Effective", IF(AND(Y11 = "Completed", Q11 >= 3), "Effective", "Needs Improvement")) -> Needs Improvement
A12: 3437 | B12: 45142 | C12: Area Sales Manager | D12: SVG | E12: Active | F12: Contract | G12: Zone B | H12: Temporary | I12: Sales | J12: Field Operations | K12: 23402 | L12: IN | M12: Female | N12: Other | O12: Single | P12: Fully Meets | Q12: 5 | R12: 44849 | S12: 3 | T12: 2 | U12: 5 | V12: 44854 | W12: Technical Skills | X12: Internal | Y12: Failed | Z12: 1 | AA12: 455.68 | AB12: 59 | AC12: {=_xlfn.IFS(AB12 <=29, "Young Adult", AB12 <=44, "Adult", AB12 <=59, "Middle Age", AB12 > 59, "Old")} -> Middle Age | AD12: =DATEDIF(B12, TODAY(), "Y") -> 2 | AE12: {=_xlfn.IFS(S12 < 3, "Low", S12 <= 4, "Medium", S12 > 4, "High")} -> Medium | AF12: {=_xlfn.IFS(T12 < 3, "Unsatisfied", T12 <= 4, "Neutral", T12 > 4, "Satisfied" )} -> Unsatisfied | AG12: {=_xlfn.IFS(Q12 < 3, "Needs Improvement", Q12 <= 4, "Good", Q12 > 4, "Excellent" )} -> Excellent | AH12: =IF(AND(Y12 = "Passed", Q12 > 4), "Highly Effective", IF(AND(Y12 = "Completed", Q12 >= 3), "Effective", "Needs Improvement")) -> Needs Improvement
A13: 3438 | B13: 43322 | C13: Area Sales Manager | D13: MSC | E13: Active | F13: Full-Time | G13: Zone C | H13: Temporary | I13: Sales | J13: General - Con | K13: 17629 | L13: GA | M13: Female | N13: Asian | O13: Married | P13: Fully Meets | Q13: 3 | R13: 44862 | S13: 4 | T13: 2 | U13: 5 | V13: 44839 | W13: Technical Skills | X13: Internal | Y13: Failed | Z13: 2 | AA13: 208.17 | AB13: 70 | AC13: {=_xlfn.IFS(AB13 <=29, "Young Adult", AB13 <=44, "Adult", AB13 <=59, "Middle Age", AB13 > 59, "Old")} -> Old | AD13: =DATEDIF(B13, TODAY(), "Y") -> 7 | AE13: {=_xlfn.IFS(S13 < 3, "Low", S13 <= 4, "Medium", S13 > 4, "High")} -> Medium | AF13: {=_xlfn.IFS(T13 < 3, "Unsatisfied", T13 <= 4, "Neutral", T13 > 4, "Satisfied" )} -> Unsatisfied | AG13: {=_xlfn.IFS(Q13 < 3, "Needs Improvement", Q13 <= 4, "Good", Q13 > 4, "Excellent" )} -> Good | AH13: =IF(AND(Y13 = "Passed", Q13 > 4), "Highly Effective", IF(AND(Y13 = "Completed", Q13 >= 3), "Effective", "Needs Improvement")) -> Needs Improvement
... A2846: 3426 | B2846: 44678 | C2846: Production Technician I | D2846: BPC | E2846: Active | F2846: Full-Time | G2846: Zone B | H2846: Temporary | I2846: Production | J2846: Field Operations | K2846: 33127 | L2846: MA | M2846: Female | N2846: White | O2846: Married | P2846: Fully Meets | Q2846: 2 | R2846: 44797 | S2846: 1 | T2846: 3 | U2846: 2 | V2846: 45048 | W2846: Leadership Development | X2846: Internal | Y2846: Failed | Z2846: 5 | AA2846: 675.37 | AB2846: 32 | AC2846: {=_xlfn.IFS(AB2846 <=29, "Young Adult", AB2846 <=44, "Adult", AB2846 <=59, "Middle Age", AB2846 > 59, "Old")} -> Adult | AD2846: =DATEDIF(B2846, TODAY(), "Y") -> 4 | AE2846: {=_xlfn.IFS(S2846 < 3, "Low", S2846 <= 4, "Medium", S2846 > 4, "High")} -> Low | AF2846: {=_xlfn.IFS(T2846 < 3, "Unsatisfied", T2846 <= 4, "Neutral", T2846 > 4, "Satisfied" )} -> Neutral | AG2846: {=_xlfn.IFS(Q2846 < 3, "Needs Improvement", Q2846 <= 4, "Good", Q2846 > 4, "Excellent" )} -> Needs Improvement | AH2846: =IF(AND(Y2846 = "Passed", Q2846 > 4), "Highly Effective", IF(AND(Y2846 = "Completed", Q2846 >= 3), "Effective", "Needs Improvement")) -> Needs Improvement

Sheet Pivot Table 1
A1: Count of Employee ID
A2: 2845
A4: Average of Age
A5: 49.448506
A7: Row Labels | B7: Count of Employee ID
A8: Male | B8: 1257
A9: Grand Total | B9: 1257
A12: Row Labels | B12: Count of Employee ID
A13: Female | B13: 1588
A14: Grand Total | B14: 1588
A16: Average of Tenure
A17: 4.7810193
A20: Row Labels | B20: Count of Employee ID
A21: Executive Office | B21: 24
A22: Admin Offices | B22: 79
A23: Software Engineering | B23: 112
A24: Sales | B24: 311
A25: IT/IS | B25: 409
A26: Production | B26: 1910
A27: Grand Total | B27: 2845
A30: Row Labels | B30: Count of Employee ID
A31: Female | B31: 1588
A32: Male | B32: 1257
A33: Grand Total | B33: 2845
A36: Row Labels | B36: Count of Employee ID
A37: NEL | B37: 291
A38: BPC | B38: 288
A39: WBL | B39: 286
A40: PYZ | B40: 285
A41: CCDR | B41: 284
A42: TNS | B42: 283
A43: PL | B43: 283
A44: EW | B44: 282
A45: MSC | B45: 282
A46: SVG | B46: 281
A47: Grand Total | B47: 2845
A50: Row Labels | B50: Count of Employee ID
A51: Young Adult | B51: 516
A52: Adult | B52: 687
A53: Middle Age | B53: 661
...

Sheet Dashboard
K73: =GETPIVOTDATA("Employee ID",'Pivot Table 1'!$A$1) -> 2845 | L73: =GETPIVOTDATA("Age",'Pivot Table 1'!$A$4) -> 49.448506 | M73: =GETPIVOTDATA("Employee ID",'Pivot Table 1'!$A$7) -> 1257 | N73: =GETPIVOTDATA("Employee ID",'Pivot Table 1'!$A$12) -> 1588 | O73: =GETPIVOTDATA("Tenure",'Pivot Table 1'!$A$16) -> 4.7810193

Sheet Pivot Table 2
A2: Average of Engagement Score
A3: 2.941652
A5: Average of Satisfaction Score
A6: 3.028471
A8: Average of Work-Life Balance Score
A9: 2.9891037
A11: Average of Current Employee Rating
A12: 2.9746924
A14: Row Labels | B14: Count of Employee ID
A15: Exceeds | B15: 346
A16: Grand Total | B16: 346
A20: ra | B20: Performance Score
A21: Admin Offices | B21: 79
A22: Executive Office | B22: 24
A23: IT/IS | B23: 409
A24: Production | B24: 1910
A25: Sales | B25: 311
A26: Software Engineering | B26: 112
A27: Grand Total | B27: 2845
A30: Row Labels | B30: Average of Satisfaction Score
A31: Safety | B31: 3.5
A32: Technology / It | B32: 3.3809524
A33: Catv | B33: 3.3148148
A34: Underground | B34: 3.2580645
A35: Executive | B35: 3.1707317
A36: General - Sga | B36: 3.1607143
A37: Aerial | B37: 3.1325967
A38: Engineers | B38: 3.1111111
A39: Isp | B39: 3.0714286
A40: Project Management - Con | B40: 3.0697674
A41: Grand Total | B41: 3.1430168
A44: Row Labels | B44: Average of Current Employee Rating
A45: Admin Offices | B45: 3.0253165
A46: Production | B46: 2.9890052
A47: IT/IS | B47: 2.9682152
A48: Sales | B48: 2.9228296
A49: Software Engineering | B49: 2.9017857
A50: Executive Office | B50: 2.7916667
A51: Grand Total | B51: 2.9746924
A53: Row Labels | B53: Average of Employee ID
...

Sheet Dasboard 2

Sheet Pivot Table 3
A1: Sum of Training Cost
A2: 1591148.6
A4: Distinct Count of Training Program Name
A5: 5
A7: Row Labels | B7: Count of Employee ID
A8: Completed | B8: 0.25905097
A9: Failed | B9: 0.23479789
A10: Incomplete | B10: 0.256942 | D10: =GETPIVOTDATA("Employee ID",$A$7,"Training Outcome","Passed") +GETPIVOTDATA("Employee ID",$A$7,"Training Outcome","Completed") -> 0.50826011
A11: Passed | B11: 0.24920914
A12: Grand Total | B12: 1
A17: Row Labels | B17: Count of Employee ID
A18: Passed | B18: 709
A19: Grand Total | B19: 709
A21: Average of Training Duration(Days)
A22: 2.9739895
A33: Row Labels | B33: Count of Employee ID
A34: Communication Skills | B34: 633
A35: Customer Service | B35: 540
A36: Leadership Development | B36: 544
A37: Project Management | B37: 585
A38: Technical Skills | B38: 543
A39: Grand Total | B39: 2845
A42: Row Labels | B42: Sum of Training Cost
A43: Admin Offices | B43: 42100.52
A44: Executive Office | B44: 14051.27
A45: IT/IS | B45: 230396.34
A46: Production | B46: 1070266.2
A47: Sales | B47: 168016.98
A48: Software Engineering | B48: 66317.37
A49: Grand Total | B49: 1591148.6
A52: Row Labels | B52: Count of Employee ID
A53: Completed | B53: 737
A54: Failed | B54: 668
A55: Incomplete | B55: 731
A56: Passed | B56: 709
A57: Grand Total | B57: 2845
A60: Count of Performance Category | B60: Column Labels
A61: Row Labels | B61: Completed | C61: Failed | D61: Incomplete | E61: Passed | F61: Grand Total
A62: External | B62: 344 | C62: 344 | D62: 380 | E62: 356 | F62: 1424
A63: Internal | B63: 393 | C63: 324 | D63: 351 | E63: 353 | F63: 1421
...

Sheet Dashboard 3
M73: =GETPIVOTDATA("Training Cost",'Pivot Table 3'!$A$1) -> 1591148.6 | N73: =GETPIVOTDATA("[Measures].[Distinct Count of Training Program Name]",'Pivot Table 3'!$A$4) -> 5 | O73: ='Pivot Table 3'!D10 -> 0.50826011 | P73: =GETPIVOTDATA("Employee ID",'Pivot Table 3'!$A$17) -> 709 | Q73: =GETPIVOTDATA("Training Duration(Days)",'Pivot Table 3'!$A$21) -> 2.9739895
